Workbook

Sheet Cover
B2: ETERNAL LIMITED (Formerly known as Zomato Limited)
B9: EQUITY RESEARCH | FINANCIAL MODEL & DCF VALUATION
B12: Prepared by: Aditi Garg | MBA | Galgotias College of Engineering and Technology
B13: Model Version: 1.0 | Date: April 2026 | For Academic Research Purposes
B15: COMPANY OVERVIEW
B17: Eternal Limited (formerly Zomato Limited) is India's largest consumer commerce platform operating across four segments: Food Delivery, Quick Commerce (Blinkit), Going-Out (District), and B2B Supplies (Hyperpure). Listed on NSE/BSE (Scrip: ETERNAL), the company achieved consolidated PAT profitability in FY24 and Blinkit EBITDA breakeven in Q3FY26.
C21: Business Description | H21: STOCK INFORMATION (As of April 2026)
C22: Sector | E22: Consumer Internet / E-Commerce | H22: Current Market Price: INR 249
C23: Industry | E23: Online Food & Quick Commerce | H23: 52-Week High | J23: INR 285
C24: Exchange | E24: NSE | BSE | H24: 52-Week Low | J24: INR 165
C25: Scrip Symbol | E25: ETERNAL | H25: Market Cap | J25: INR ₹ 2,46,595 Cr
C26: ISIN | E26: INE758T01015 | H26: Enterprise Value | J26: INR ₹ 2,33,886 Cr
C27: Face Value | E27: INR 1 per share | H27: Shares Outstanding | J27: 906 Cr (Basic) | 940 Cr (Diluted)
C28: Listing Date | E28: 44400 | H28: Free Float | J28: 0.63
C29: Auditor | E29: Deloitte Haskins & Sells | H29: Foreign Holding - 36.68%
C30: Registrar | E30: MUFG Intime India Pvt. Ltd. | H30: Promoter Holding: 0% (widely held)
C31: Company Website | E31: www.eternal.com | H31: Index Constituent - Nifty 50 | Sensex
C32: IR Contact | E32: ir@eternal.com | H32: Bloomberg Ticker - ETERNAL IN Equity
B34: KEY FINANCIAL METRICS TABLE | ₹ Crores
C36: Metric | E36: FY22A | F36: FY23A | G36: FY24A | H36: FY25A | I36: FY26E | J36: FY27E | K36: FY28E | L36: FY29E
C37: Revenue from Operations | E37: ='Historical Financials'!C12 -> 4193 | F37: ='Historical Financials'!D12 -> 7079 | G37: ='Historical Financials'!E12 -> 12114 | H37: ='Historical Financials'!F12 -> 20243 | I37: ='3-Statement'!G7 -> 28641.422 | J37: ='3-Statement'!H7 -> 40122.272 | K37: ='3-Statement'!I7 -> 53093.729 | L37: ='3-Statement'!J7 -> 65159.791
C38: Revenue Growth % | E38: - | F38: =F37/E37-1 -> 0.68829001 | G38: =G37/F37-1 -> 0.71125865 | H38: =H37/G37-1 -> 0.67104177 | I38: =I37/H37-1 -> 0.41488029 | J38: =J37/I37-1 -> 0.40084779 | K38: =K37/J37-1 -> 0.32329816 | L38: =L37/K37-1 -> 0.22725964
C39: Adj. EBITDA | E39: ='3-Statement'!C27 -> -973 | F39: ='3-Statement'!D27 -> -765 | G39: ='3-Statement'!E27 -> 372 | H39: ='3-Statement'!F27 -> 1079 | I39: ='3-Statement'!G27 -> 2274.8515 | J39: ='3-Statement'!H27 -> 3753.0491 | K39: ='3-Statement'!I27 -> 6529.8646 | L39: ='3-Statement'!J27 -> 9407.7513
C40: Adj. EBITDA Margin % | E40: ='3-Statement'!C28 -> -0.23205342 | F40: ='3-Statement'!D28 -> -0.10806611 | G40: ='3-Statement'!E28 -> 0.030708271 | H40: ='3-Statement'!F28 -> 0.053302376 | I40: ='3-Statement'!G28 -> 0.079425229 | J40: ='3-Statement'!H28 -> 0.093540291 | K40: ='3-Statement'!I28 -> 0.12298749 | L40: ='3-Statement'!J28 -> 0.1443797
C41: EBIT | E41: ='3-Statement'!C38 -> -1519 | F41: ='3-Statement'!D38 -> -1342 | G41: ='3-Statement'!E38 -> -553 | H41: ='3-Statement'!F38 -> 216 | I41: ='3-Statement'!G38 -> 1144.8515 | J41: ='3-Statement'!H38 -> 2373.0491 | K41: ='3-Statement'!I38 -> 4939.8646 | L41: ='3-Statement'!J38 -> 7667.7513
C42: Profit Before Tax | E42: ='3-Statement'!C45 -> -1221 | F42: ='3-Statement'!D45 -> -1015 | G42: ='3-Statement'!E45 -> 291 | H42: ='3-Statement'!F45 -> 697 | I42: ='3-Statement'!G45 -> 1960.8515 | J42: ='3-Statement'!H45 -> 2956.0491 | K42: ='3-Statement'!I45 -> 5357.8646 | L42: ='3-Statement'!J45 -> 7990.7513
C43: Profit After Tax | E43: ='3-Statement'!C53 -> -1223 | F43: ='3-Statement'!D53 -> -971 | G43: ='3-Statement'!E53 -> 351 | H43: ='3-Statement'!F53 -> 527 | I43: ='3-Statement'!G53 -> 1593.8515 | J43: ='3-Statement'!H53 -> 2357.0491 | K43: ='3-Statement'!I53 -> 4064.8646 | L43: ='3-Statement'!J53 -> 6038.7513
C44: PAT Margin % | E44: ='3-Statement'!C54 -> -0.2916766 | F44: ='3-Statement'!D54 -> -0.13716627 | G44: ='3-Statement'!E54 -> 0.02897474 | H44: ='3-Statement'!F54 -> 0.026033691 | I44: ='3-Statement'!G54 -> 0.055648476 | J44: ='3-Statement'!H54 -> 0.058746649 | K44: ='3-Statement'!I54 -> 0.076560164 | L44: ='3-Statement'!J54 -> 0.092676039
C45: EPS (INR) | E45: ='3-Statement'!C55 -> -1.6007853 | F45: ='3-Statement'!D55 -> -1.1614833 | G45: ='3-Statement'!E55 -> 0.40437788 | H45: ='3-Statement'!F55 -> 0.58103638 | I45: ='3-Statement'!G55 -> 1.6955867 | J45: ='3-Statement'!H55 -> 2.4552594 | K45: ='3-Statement'!I55 -> 4.1690919 | L45: ='3-Statement'!J55 -> 6.130712
C46: Total Assets | E46: ='3-Statement'!C83 -> 17327 | F46: ='3-Statement'!D83 -> 21602 | G46: ='3-Statement'!E83 -> 23356 | H46: ='3-Statement'!F83 -> 35623 | I46: ='3-Statement'!G83 -> 38686.851 | J46: ='3-Statement'!H83 -> 43937.901 | K46: ='3-Statement'!I83 -> 50517.765 | L46: ='3-Statement'!J83 -> 58514.517
C47: Total Equity | E47: ='3-Statement'!C89 -> 16499 | F47: ='3-Statement'!D89 -> 19452 | G47: ='3-Statement'!E89 -> 20406 | H47: ='3-Statement'!F89 -> 30310 | I47: ='3-Statement'!G89 -> 32836.851 | J47: ='3-Statement'!H89 -> 36160.901 | K47: ='3-Statement'!I89 -> 41135.765 | L47: ='3-Statement'!J89 -> 48034.517
C48: Cash Position | E48: ='3-Statement'!C76 -> 392 | F48: ='3-Statement'!D76 -> 218 | G48: ='3-Statement'!E76 -> 309 | H48: ='3-Statement'!F76 -> 666 | I48: ='3-Statement'!G76 -> 28.851476 | J48: ='3-Statement'!H76 -> 371.90053 | K48: ='3-Statement'!I76 -> 1820.7652 | L48: ='3-Statement'!J76 -> 5090.5165
B50: VALUATION SUMMARY & INVESTMENT RECOMMENDATION
B52: Label | D52: Value | E52: Notes | H52: INVESTMENT RATING H O L D Current Price: INR 249 Target Price: INR 211 Upside/(Downside): (15.3%) Time Horizon: 12 Months Risk Level: HIGH
B53: DCF Base Case | D53: ="₹" & ROUND('SOTP Valution'!D40,0) -> ₹170 | E53: WACC 13.95%, g=6.0%
B54: DCF Bull Case | D54: ="₹" & ROUND('SOTP Valution'!E40,0) -> ₹229 | E54: WACC 12.65%, g=6.5%
B55: DCF Bear Case | D55: ="₹" & ROUND('SOTP Valution'!C40,0) -> ₹149 | E55: WACC 15.9%, g=5.0%
B56: EV/Revenue Comps | D56: INR 137 | E56: 3.5x FY26E Revenue
B57: EV/EBITDA Comps | D57: INR 126 | E57: 23x FY26E Adj. EBITDA
B58: P/E Comps | D58: INR 154 | E58: 40x FY26E EPS
...

Sheet Historical Financials
B2: Historical financial Statement - ETERNAL LIMITED | ₹ Crores
B3: Particulars | C3: FY2022A | D3: FY2023A | E3: FY2024A | F3: FY2025A
A5: # | B5: Income Statement (₹ Crores)
B6: Revenue from Operations
B7: Food Delivery Platform Revenue | C7: 3415 | D7: 4533 | E7: 6361 | F7: 8080
B8: Blinkit Quick Commerce Revenue | C8: - | D8: 806 | E8: 2301 | F8: 5206
B9: Hyperpure B2B Supplies Revenue | C9: 538 | D9: 1506 | E9: 3172 | F9: 6196
B10: District / Going Out Revenue | C10: - | D10: - | E10: 258 | F10: 737
B11: Bistro & Others Revenue | C11: 240 | D11: 234 | E11: 22 | F11: 24
B12: Total Revenue from Operations | C12: =SUM(C7:C11) -> 4193 | D12: =SUM(D7:D11) -> 7079 | E12: =SUM(E7:E11) -> 12114 | F12: =SUM(F7:F11) -> 20243
B13: YoY Revenue Growth % | C13: - | D13: =D12/C12-1 -> 0.68829001 | E13: =E12/D12-1 -> 0.71125865 | F13: =F12/E12-1 -> 0.67104177
B15: Other Income | C15: 495 | D15: 681 | E15: 847 | F15: 1077
B16: TOTAL INCOME | C16: =SUM(C15,C12) -> 4688 | D16: =SUM(D15,D12) -> 7760 | E16: =SUM(E15,E12) -> 12961 | F16: =SUM(F15,F12) -> 21320
B18: COST OF REVENUE
B19: Purchases of Stock-in-Trade | C19: 552 | D19: 1438 | E19: 2887 | F19: 5653
B20: Changes in Inventories of Stock-in-Trade | C20: -43 | D20: -28 | E20: -5 | F20: -88
B21: Delivery Partner & Fulfilment Costs | C21: 1814 | D21: 2537 | E21: 3915 | F21: 5728
B23: Gross Profit | C23: =C12-C19-C20-C21 -> 1870 | D23: =D12-D19-D20-D21 -> 3132 | E23: =E12-E19-E20-E21 -> 5317 | F23: =F12-F19-F20-F21 -> 8950
B24: Gross Margin % of Revenue | C24: =C23/C12 -> 0.4459814 | D24: =D23/D12 -> 0.44243537 | E24: =E23/E12 -> 0.43891365 | F24: =F23/F12 -> 0.44212814
B26: PEOPLE COSTS
B27: Employee Benefits Expense (Cash) | C27: 755 | D27: 959 | E27: 1144 | F27: 1760
B28: ESOP / Share-Based Compensation Expense | C28: 878 | D28: 506 | E28: 515 | F28: 798
B29: Total People Costs | C29: =SUM(C27:C28) -> 1633 | D29: =SUM(D27:D28) -> 1465 | E29: =SUM(E27:E28) -> 1659 | F29: =SUM(F27:F28) -> 2558
B31: OPERATING EXPENSES
B32: Advertising & Marketing Expense | C32: 1633 | D32: 1465 | E32: 526 | F32: 863
B33: Technology & Platform Infrastructure Costs | C33: 289 | D33: 387 | E33: 485 | F33: 644
B34: Short-term Lease & Facility Costs | C34: 10 | D34: 42 | E34: 44 | F34: 68
B35: Warehousing Management Expenses | C35: 25 | D35: 129 | E35: 211 | F35: 400
B36: Outsourced Support Cost | C36: 172 | D36: 297 | E36: 330 | F36: 570
B37: Payment Gateway Charges | C37: 119 | D37: 155 | E37: 190 | F37: 228
B38: Other Operating Expenses | C38: 1254 | D38: 1185 | E38: 2839 | F38: 7601
B39: Other Expenses | C39: 353 | D39: 1770 | E39: 2906 | F39: 1109
B40: Total Other Expenses | C40: =SUM(C32:C39) -> 3855 | D40: =SUM(D32:D39) -> 5430 | E40: =SUM(E32:E39) -> 7531 | F40: =SUM(F32:F39) -> 11483
B42: ADJUSTED EBITDA | C42: =SUM(C46:C51) -> -973 | D42: =SUM(D46:D51) -> -765 | E42: =SUM(E46:E51) -> 372 | F42: =SUM(F46:F51) -> 1079
B43: Adj. EBITDA Margin % | C43: =C42/C12 -> -0.23205342 | D43: =D42/D12 -> -0.10806611 | E43: =E42/E12 -> 0.030708271 | F43: =F42/F12 -> 0.053302376
B45: Segment-wise Adj. EBITDA:
B46: - Food | C46: -766 | D46: -5 | E46: 912 | F46: 1505
B47: - Blinkit | C47: - | D47: -1016 | E47: -384 | F47: -292
B48: - Hyperpure | C48: -139 | D48: -194 | E48: -126 | F48: -84
B49: - District/Going Out | C49: - | D49: - | E49: -6 | F49: -38
...

Sheet KPIs
B2: KPI - ETERNAL LIMITED | ₹ Crores
B3: Particulars | C3: FY2022A | D3: FY2023A | E3: FY2024A | F3: FY2025A
A5: # | B5: GROUP-LEVEL FINANCIAL KPIs
B6: Total Revenue from Operations (₹ Cr) | C6: ='Historical Financials'!C12 -> 4193 | D6: ='Historical Financials'!D12 -> 7079 | E6: ='Historical Financials'!E12 -> 12114 | F6: ='Historical Financials'!F12 -> 20243
B7: YoY Revenue Growth % | C7: ='Historical Financials'!C13 -> - | D7: ='Historical Financials'!D13 -> 0.68829001 | E7: ='Historical Financials'!E13 -> 0.71125865 | F7: ='Historical Financials'!F13 -> 0.67104177
B8: Gross Profit (₹ Cr) | C8: ='Historical Financials'!C23 -> 1870 | D8: ='Historical Financials'!D23 -> 3132 | E8: ='Historical Financials'!E23 -> 5317 | F8: ='Historical Financials'!F23 -> 8950
B9: Gross Margin % | C9: ='Historical Financials'!C24 -> 0.4459814 | D9: ='Historical Financials'!D24 -> 0.44243537 | E9: ='Historical Financials'!E24 -> 0.43891365 | F9: ='Historical Financials'!F24 -> 0.44212814
B10: Adjusted EBITDA (₹ Cr) | C10: ='Historical Financials'!C42 -> -973 | D10: ='Historical Financials'!D42 -> -765 | E10: ='Historical Financials'!E42 -> 372 | F10: ='Historical Financials'!F42 -> 1079
B11: Adjusted EBITDA Margin % | C11: ='Historical Financials'!C43 -> -0.23205342 | D11: ='Historical Financials'!D43 -> -0.10806611 | E11: ='Historical Financials'!E43 -> 0.030708271 | F11: ='Historical Financials'!F43 -> 0.053302376
B12: Reported EBITDA (₹ Cr) | C12: ='Historical Financials'!C59 -> -1851 | D12: ='Historical Financials'!D59 -> -1271 | E12: ='Historical Financials'!E59 -> -143 | F12: ='Historical Financials'!F59 -> 281
B13: Reported EBITDA Margin % | C13: ='Historical Financials'!C60 -> -0.44145004 | D13: ='Historical Financials'!D60 -> -0.17954513 | E13: ='Historical Financials'!E60 -> -0.011804524 | F13: ='Historical Financials'!F60 -> 0.013881342
B14: EBIT (₹ Cr) | C14: ='Historical Financials'!C61 -> -1519 | D14: ='Historical Financials'!D61 -> -1342 | E14: ='Historical Financials'!E61 -> -553 | F14: ='Historical Financials'!F61 -> 216
B15: EBIT Margin % | C15: ='Historical Financials'!C62 -> -0.36227045 | D15: ='Historical Financials'!D62 -> -0.1895748 | E15: ='Historical Financials'!E62 -> -0.045649662 | F15: ='Historical Financials'!F62 -> 0.010670355
B16: PBT (₹ Cr) | C16: ='Historical Financials'!C68 -> -1221 | D16: ='Historical Financials'!D68 -> -1015 | E16: ='Historical Financials'!E68 -> 291 | F16: ='Historical Financials'!F68 -> 697
B17: PBT Margin % | C17: ='Historical Financials'!C69 -> -0.29119962 | D17: ='Historical Financials'!D69 -> -0.14338183 | E17: ='Historical Financials'!E69 -> 0.024021793 | F17: ='Historical Financials'!F69 -> 0.034431655
B18: PAT (₹ Cr) | C18: ='Historical Financials'!C76 -> -1223 | D18: ='Historical Financials'!D76 -> -971 | E18: ='Historical Financials'!E76 -> 351 | F18: ='Historical Financials'!F76 -> 527
B19: PAT Margin % | C19: ='Historical Financials'!C77 -> -0.2916766 | D19: ='Historical Financials'!D77 -> -0.13716627 | E19: ='Historical Financials'!E77 -> 0.02897474 | F19: ='Historical Financials'!F77 -> 0.026033691
B20: Basic EPS (₹) | C20: ='Historical Financials'!C79 -> -1.6007853 | D20: ='Historical Financials'!D79 -> -1.1614833 | E20: ='Historical Financials'!E79 -> 0.40437788 | F20: ='Historical Financials'!F79 -> 0.58103638
B21: Diluted EPS (₹) | C21: ='Historical Financials'!C80 -> -1.67 | D21: ='Historical Financials'!D80 -> -1.2 | E21: ='Historical Financials'!E80 -> 0.4 | F21: ='Historical Financials'!F80 -> 0.58
B22: Book Value Per Share (₹) | C22: ='Historical Financials'!C113/C218 -> 21.587073 | D22: ='Historical Financials'!D113/D218 -> 23.256815 | E22: ='Historical Financials'!E113/E218 -> 23.509217 | F22: ='Historical Financials'!F113/F218 -> 33.406811
B24: COST STRUCTURE KPIs
B25: Employee Cost (% of Revenue) | C25: ='Historical Financials'!C29/'Historical Financials'!C12 -> 0.38945862 | D25: ='Historical Financials'!D29/'Historical Financials'!D12 -> 0.20695013 | E25: ='Historical Financials'!E29/'Historical Financials'!E12 -> 0.13694898 | F25: ='Historical Financials'!F29/'Historical Financials'!F12 -> 0.12636467
B26: ESOP (% of Revenue) | C26: ='Historical Financials'!C28/'Historical Financials'!C12 -> 0.20939661 | D26: ='Historical Financials'!D28/'Historical Financials'!D12 -> 0.071479022 | E26: ='Historical Financials'!E28/'Historical Financials'!E12 -> 0.042512795 | F26: ='Historical Financials'!F28/'Historical Financials'!F12 -> 0.039421034
B27: Cash Employee Cost (% of Revenue) | C27: =C25-C26 -> 0.18006201 | D27: =D25-D26 -> 0.13547111 | E27: =E25-E26 -> 0.09443619 | F27: =F25-F26 -> 0.086943635
B28: Marketing & Advertising (% of Revenue) | C28: ='Historical Financials'!C32/'Historical Financials'!C12 -> 0.38945862 | D28: ='Historical Financials'!D32/'Historical Financials'!D12 -> 0.20695013 | E28: ='Historical Financials'!E32/'Historical Financials'!E12 -> 0.043420835 | F28: ='Historical Financials'!F32/'Historical Financials'!F12 -> 0.042632021
B29: Technology Cost (% of Revenue) | C29: ='Historical Financials'!C33/'Historical Financials'!C12 -> 0.068924398 | D29: ='Historical Financials'!D33/'Historical Financials'!D12 -> 0.054668739 | E29: ='Historical Financials'!E33/'Historical Financials'!E12 -> 0.040036322 | F29: ='Historical Financials'!F33/'Historical Financials'!F12 -> 0.031813466
B30: Delivery & Fulfilment (% of Revenue) | C30: ='Historical Financials'!C21/'Historical Financials'!C12 -> 0.4326258 | D30: ='Historical Financials'!D21/'Historical Financials'!D12 -> 0.35838395 | E30: ='Historical Financials'!E21/'Historical Financials'!E12 -> 0.32317979 | F30: ='Historical Financials'!F21/'Historical Financials'!F12 -> 0.28296201
B31: Total Other Expenses (% of Revenue) | C31: ='Historical Financials'!C40/'Historical Financials'!C12 -> 0.91938946 | D31: ='Historical Financials'!D40/'Historical Financials'!D12 -> 0.76705749 | E31: ='Historical Financials'!E40/'Historical Financials'!E12 -> 0.6216774 | F31: ='Historical Financials'!F40/'Historical Financials'!F12 -> 0.56725782
B33: CAPITAL EFFICIENCY KPIs
B34: Return on Equity (%) | C34: ='Historical Financials'!C76/'Historical Financials'!C113 -> -0.074125705 | D34: ='Historical Financials'!D76/'Historical Financials'!D113 -> -0.049917746 | E34: ='Historical Financials'!E76/'Historical Financials'!E113 -> 0.017200823 | F34: ='Historical Financials'!F76/'Historical Financials'!F113 -> 0.017387001
B35: Return on Capital Employed (%) | C35: ='Historical Financials'!C61/('Historical Financials'!C113+'Historical Financials'!C121) -> -0.09141791 | D35: ='Historical Financials'!D61/('Historical Financials'!D113+'Historical Financials'!D121) -> -0.066577368 | E35: ='Historical Financials'!E61/('Historical Financials'!E113+'Historical Financials'!E121) -> -0.025995393 | F35: ='Historical Financials'!F61/('Historical Financials'!F113+'Historical Financials'!F121) -> 0.0066879277
B36: Asset Turnover (x) | C36: ='Historical Financials'!C12/'Historical Financials'!C107 -> 0.24199227 | D36: ='Historical Financials'!D12/'Historical Financials'!D107 -> 0.32770114 | E36: ='Historical Financials'!E12/'Historical Financials'!E107 -> 0.51866758 | F36: ='Historical Financials'!F12/'Historical Financials'!F107 -> 0.56825646
B37: Capex (% of Revenue) | C37: =ABS('Historical Financials'!C178)/'Historical Financials'!C12 -> 0.014071071 | D37: =ABS('Historical Financials'!D178)/'Historical Financials'!D12 -> 0.014550078 | E37: =ABS('Historical Financials'!E178)/'Historical Financials'!E12 -> 0.01774806 | F37: =ABS('Historical Financials'!F178)/'Historical Financials'!F12 -> 0.046238206
B38: Capex (% of Adj EBITDA) | C38: =ABS('Historical Financials'!C178)/ABS(C10) -> 0.060637205 | D38: =ABS('Historical Financials'!D178)/ABS(D10) -> 0.13464052 | E38: =ABS('Historical Financials'!E178)/ABS(E10) -> 0.57795699 | F38: =ABS('Historical Financials'!F178)/ABS(F10) -> 0.86746988
B40: WORKING CAPITAL KPIs
B41: Debtor Days | C41: ='Historical Financials'!C99/'Historical Financials'!C12*365 -> 1.3927975 | D41: ='Historical Financials'!D99/'Historical Financials'!D12*365 -> 2.320243 | E41: ='Historical Financials'!E99/'Historical Financials'!E12*365 -> 23.471603 | F41: ='Historical Financials'!F99/'Historical Financials'!F12*365 -> 35.088179
B42: Creditor Days | C42: =('Historical Financials'!C125+'Historical Financials'!C126)/'Historical Financials'!C12*365 -> 37.344383 | D42: =('Historical Financials'!D125+'Historical Financials'!D126)/'Historical Financials'!D12*365 -> 35.061449 | E42: =('Historical Financials'!E125+'Historical Financials'!E126)/'Historical Financials'!E12*365 -> 26.695559 | F42: =('Historical Financials'!F125+'Historical Financials'!F126)/'Historical Financials'!F12*365 -> 27.6955
B43: Inventory Days | C43: ='Historical Financials'!C97/'Historical Financials'!C12*365 -> 3.4819938 | D43: ='Historical Financials'!D97/'Historical Financials'!D12*365 -> 4.2795593 | E43: ='Historical Financials'!E97/'Historical Financials'!E12*365 -> 2.6514776 | F43: ='Historical Financials'!F97/'Historical Financials'!F12*365 -> 3.1734427
B44: Cash Conversion Ratio (CFO/PAT) | C44: =ROUND(('Historical Financials'!C175/'Historical Financials'!C76),2) & "x" -> 0.44x | D44: =ROUND(('Historical Financials'!D175/'Historical Financials'!D76),2) & "x" -> 0.87x | E44: =ROUND(('Historical Financials'!E175/'Historical Financials'!E76),2) & "x" -> 1.84x | F44: =ROUND(('Historical Financials'!F175/'Historical Financials'!F76),2) & "x" -> 0.58x
B45: CFO / Adjusted EBITDA | C45: =ROUND('Historical Financials'!C175/ABS(C10),2) & "x" -> -0.55x | D45: =ROUND('Historical Financials'!D175/ABS(D10),2) & "x" -> -1.1x | E45: =ROUND('Historical Financials'!E175/ABS(E10),2) & "x" -> 1.74x | F45: =ROUND('Historical Financials'!F175/ABS(F10),2) & "x" -> 0.29x
...

Sheet Assumptions
B2: Assumptions - ETERNAL LIMITED | ₹ Crores
B3: Scenario | C3: Base Case
B4: =MATCH(TRIM(C3),{"Bear Case","Base Case","Bull Case"},0) -> 2
B5: Items | C5: Scenario | D5: FY25A | E5: FY26E | F5: FY27E | G5: FY28E | H5: FY29E | I5: Notes/Sources
A7: # | B7: FOOD DELIVERY ASSUMPTIONS
B8: FD GOV Growth % YoY | C8: Bear Case | E8: 0.13 | F8: 0.15 | G8: 0.14 | H8: 0.12
C9: Base Case | E9: 0.18 | F9: 0.2 | G9: 0.19 | H9: 0.17
C10: Bull Case | E10: 0.23 | F10: 0.25 | G10: 0.22 | H10: 0.2
B11: FD GOV Growth % YoY | C11: Active | E11: =IF($B$4=1,E8,IF($B$4=2,E9,E10)) -> 0.18 | F11: =IF($B$4=1,F8,IF($B$4=2,F9,F10)) -> 0.2 | G11: =IF($B$4=1,G8,IF($B$4=2,G9,G10)) -> 0.19 | H11: =IF($B$4=1,H8,IF($B$4=2,H9,H10)) -> 0.17 | I11: Q2FY26 concall: 'expecting 15% this year; 20%+ long term'
B13: FD Take Rate (Rev÷GOV) | C13: Bear Case | D13: 0.209 | E13: 0.205 | F13: 0.21 | G13: 0.215 | H13: 0.215
C14: Base Case | E14: 0.215 | F14: 0.22 | G14: 0.225 | H14: 0.225
C15: Bull Case | E15: 0.22 | F15: 0.225 | G15: 0.23 | H15: 0.235
B16: FD Take Rate (Rev÷GOV) | C16: Active | D16: =D13 -> 0.209 | E16: =IF($B$4=1,E13,IF($B$4=2,E14,E15)) -> 0.215 | F16: =IF($B$4=1,F13,IF($B$4=2,F14,F15)) -> 0.22 | G16: =IF($B$4=1,G13,IF($B$4=2,G14,G15)) -> 0.225 | H16: =IF($B$4=1,H13,IF($B$4=2,H14,H15)) -> 0.225 | I16: FY22: 16% → FY25: 20.9%. Ceiling 22.5% - rest. pushback risk
B18: FD EBITDA Margin % NOV | C18: Bear Case | D18: 0.046 | E18: 0.048 | F18: 0.05 | G18: 0.052 | H18: 0.053
C19: Base Case | E19: 0.052 | F19: 0.055 | G19: 0.057 | H19: 0.058
C20: Bull Case | E20: 0.056 | F20: 0.058 | G20: 0.06 | H20: 0.06
B21: FD EBITDA Margin % NOV | C21: Active | D21: =D18 -> 0.046 | E21: =IF($B$4=1,E18,IF($B$4=2,E19,E20)) -> 0.052 | F21: =IF($B$4=1,F18,IF($B$4=2,F19,F20)) -> 0.055 | G21: =IF($B$4=1,G18,IF($B$4=2,G19,G20)) -> 0.057 | H21: =IF($B$4=1,H18,IF($B$4=2,H19,H20)) -> 0.058 | I21: Postal ballot Feb 2026: steady state 5-6% of NOV confirmed
B23: FD MTU (mn) | C23: Bear Case | D23: 20.6 | E23: 21.5 | F23: 23 | G23: 24.5 | H23: 26
C24: Base Case | E24: 22.5 | F24: 24.5 | G24: 26.5 | H24: 28.5
C25: Bull Case | E25: 23.5 | F25: 26 | G25: 28.5 | H25: 31
B26: FD MTU (mn) | C26: Active | D26: =D23 -> 20.6 | E26: =IF($B$4=1,E23,IF($B$4=2,E24,E25)) -> 22.5 | F26: =IF($B$4=1,F23,IF($B$4=2,F24,F25)) -> 24.5 | G26: =IF($B$4=1,G23,IF($B$4=2,G24,G25)) -> 26.5 | H26: =IF($B$4=1,H23,IF($B$4=2,H24,H25)) -> 28.5 | I26: FY22-25 avg 12% growth; decelerating to 9%
B28: FD AOV (₹) | C28: Bear Case | D28: 453 | E28: 468 | F28: 487 | G28: 507 | H28: 527
C29: Base Case | E29: 473 | F29: 493 | G29: 514 | H29: 536
C30: Bull Case | E30: 478 | F30: 500 | G30: 522 | H30: 545
B31: FD AOV (₹) | C31: Active | D31: =D28 -> 453 | E31: =IF($B$4=1,E28,IF($B$4=2,E29,E30)) -> 473 | F31: =IF($B$4=1,F28,IF($B$4=2,F29,F30)) -> 493 | G31: =IF($B$4=1,G28,IF($B$4=2,G29,G30)) -> 514 | H31: =IF($B$4=1,H28,IF($B$4=2,H29,H30)) -> 536 | I31: Historical CAGR 4.4%; using 4.5%/yr premium mix
A34: # | B34: BLINKIT QUICK COMMERCE (Probability-Weighted: 40% Rational / 60% Irrational)
B35: Blinkit NOV Growth % YoY | C35: Bear Case | D35: 1.13 | E35: 0.35 | F35: 0.35 | G35: 0.25 | H35: 0.15
C36: Base Case | E36: 0.5 | F36: 0.5 | G36: 0.35 | H36: 0.2
C37: Bull Case | E37: 0.9 | F37: 0.65 | G37: 0.45 | H37: 0.28
B38: Blinkit NOV Growth % YoY | C38: Active | D38: =D35 -> 1.13 | E38: =IF($B$4=1,E35,IF($B$4=2,E36,E37)) -> 0.5 | F38: =IF($B$4=1,F35,IF($B$4=2,F36,F37)) -> 0.5 | G38: =IF($B$4=1,G35,IF($B$4=2,G36,G37)) -> 0.35 | H38: =IF($B$4=1,H35,IF($B$4=2,H36,H37)) -> 0.2 | I38: Q2FY26 run-rate 137%; H2FY26 suppressed by competition
B40: Blinkit Take Rate (Rev÷NOV) | C40: Bear Case | D40: 0.233 | E40: 0.225 | F40: 0.23 | G40: 0.235 | H40: 0.24
C41: Base Case | E41: 0.235 | F41: 0.24 | G41: 0.245 | H41: 0.25
C42: Bull Case | E42: 0.24 | F42: 0.25 | G42: 0.26 | H42: 0.27
B43: Blinkit Take Rate (Rev÷NOV) | C43: Active | D43: =D40 -> 0.233 | E43: =IF($B$4=1,E40,IF($B$4=2,E41,E42)) -> 0.235 | F43: =IF($B$4=1,F40,IF($B$4=2,F41,F42)) -> 0.24 | G43: =IF($B$4=1,G40,IF($B$4=2,G41,G42)) -> 0.245 | H43: =IF($B$4=1,H40,IF($B$4=2,H41,H42)) -> 0.25 | I43: 1P model 90% → full gross revenue recognition; ad rev growing
B45: Blinkit EBITDA Margin % NOV | C45: Bear Case | E45: 0 | F45: 0.005 | G45: 0.015 | H45: 0.025
C46: Base Case | E46: 0.01 | F46: 0.02 | G46: 0.035 | H46: 0.045
C47: Bull Case | E47: 0.025 | F47: 0.04 | G47: 0.055 | H47: 0.065
B48: Blinkit EBITDA Margin % NOV | C48: Active | E48: =IF($B$4=1,E45,IF($B$4=2,E46,E47)) -> 0.01 | F48: =IF($B$4=1,F45,IF($B$4=2,F46,F47)) -> 0.02 | G48: =IF($B$4=1,G45,IF($B$4=2,G46,G47)) -> 0.035 | H48: =IF($B$4=1,H45,IF($B$4=2,H46,H47)) -> 0.045 | I48: Base=prob.weighted. Mgmt SS target 5-6% NOV. Q3FY26 breakeven achieved
B50: Dark Store Count (EoY) | C50: Bear Case | D50: 1301 | E50: 1800 | F50: 2300 | G50: 2900 | H50: 3400
C51: Base Case | E51: 1950 | F51: 2600 | G51: 3300 | H51: 3700
...

Sheet Revenue Model
B2: REVENUE MODEL - ETERNAL LIMITED
B3: Particulars | C3: FY22A | D3: FY23A | E3: FY24A | F3: FY25A | G3: FY26E | H3: FY27E | I3: FY28E | J3: FY29E
B5: A. FOOD DELIVERY
B6: Operating Metrics
B7: Gross Order Value - GOV | C7: =KPIs!C89 -> 21300 | D7: =KPIs!D89 -> 26305 | E7: =KPIs!E89 -> 32224 | F7: =KPIs!F89 -> 38646 | G7: =F7*(1+Assumptions!E11) -> 45602.28 | H7: =G7*(1+Assumptions!F11) -> 54722.736 | I7: =H7*(1+Assumptions!G11) -> 65120.056 | J7: =I7*(1+Assumptions!H11) -> 76190.465
B8: NOV % of GOV | C8: - | D8: 0.855 | E8: 0.853 | F8: 0.85 | G8: 0.85 | H8: 0.845 | I8: 0.84 | J8: 0.835
B9: Net Order Value - NOV | C9: - | D9: =D7*D8 -> 22490.775 | E9: =E7*E8 -> 27487.072 | F9: =F7*F8 -> 32849.1 | G9: =G7*G8 -> 38761.938 | H9: =H7*H8 -> 46240.712 | I9: =I7*I8 -> 54700.847 | J9: =J7*J8 -> 63619.039
B10: MTU (mn) | C10: =KPIs!C100 -> 14.7 | D10: =KPIs!D100 -> 17 | E10: =KPIs!E100 -> 18.4 | F10: =KPIs!F100 -> 20.6 | G10: =Assumptions!E26 -> 22.5 | H10: =Assumptions!F26 -> 24.5 | I10: =Assumptions!G26 -> 26.5 | J10: =Assumptions!H26 -> 28.5
B11: AOV (₹) | C11: =KPIs!C98 -> 398 | D11: =KPIs!D98 -> 407 | E11: =KPIs!E98 -> 428 | F11: =KPIs!F98 -> 453 | G11: =Assumptions!E31 -> 473 | H11: =Assumptions!F31 -> 493 | I11: =Assumptions!G31 -> 514 | J11: =Assumptions!H31 -> 536
B12: Annual Orders (mn) | C12: =KPIs!C97 -> 535 | D12: =KPIs!D97 -> 647 | E12: =KPIs!E97 -> 753 | F12: =KPIs!F97 -> 853 | G12: =G10*12*3.45 -> 931.5 | H12: =H10*12*3.45 -> 1014.3 | I12: =I10*12*3.45 -> 1097.1 | J12: =J10*12*3.45 -> 1179.9
B13: Avg Monthly Active Restaurants ('000) | C13: =KPIs!C108 -> 180 | D13: =KPIs!D108 -> 210 | E13: =KPIs!E108 -> 247 | F13: =KPIs!F108 -> 297 | G13: =F13*1.11 -> 329.67 | H13: =G13*1.1 -> 362.637 | I13: =H13*1.1 -> 398.9007 | J13: =I13*1.09 -> 434.80176
B14: Avg Monthly Active Delivery Partners ('000) | C14: =KPIs!C103 -> 285 | D14: =KPIs!D103 -> 326 | E14: =KPIs!E103 -> 400 | F14: =KPIs!F103 -> 473 | G14: =F14*1.11 -> 525.03 | H14: =G14*1.1 -> 577.533 | I14: =H14*1.1 -> 635.2863 | J14: =I14*1.09 -> 692.46207
B16: Revenue Build
B17: Take Rate | C17: - | D17: =KPIs!D105 -> 0.172 | E17: =KPIs!E105 -> 0.197 | F17: =KPIs!F105 -> 0.209 | G17: =Assumptions!E16 -> 0.215 | H17: =Assumptions!F16 -> 0.22 | I17: =Assumptions!G16 -> 0.225 | J17: =Assumptions!H16 -> 0.225
B18: Food Delivery Platform Revenue | C18: =KPIs!C91 -> 3415 | D18: =KPIs!D91 -> 4533 | E18: =KPIs!E91 -> 6361 | F18: =KPIs!F91 -> 8080 | G18: =G7*G17 -> 9804.4902 | H18: =H7*H17 -> 12039.002 | I18: =I7*I17 -> 14652.013 | J18: =J7*J17 -> 17142.855
B20: Profitability
B21: Adj EBITDA Margin % of NOV | C21: =KPIs!C116 -> -0.036 | D21: =KPIs!D116 -> 0 | E21: =KPIs!E116 -> 0.033 | F21: =KPIs!F116 -> 0.046 | G21: =Assumptions!E21 -> 0.052 | H21: =Assumptions!F21 -> 0.055 | I21: =Assumptions!G21 -> 0.057 | J21: =Assumptions!H21 -> 0.058
B22: Adj EBITDA - Food Delivery | C22: =KPIs!C115 -> -766 | D22: =KPIs!D115 -> -10 | E22: =KPIs!E115 -> 912 | F22: =KPIs!F115 -> 1505 | G22: =G9*G21 -> 2015.6208 | H22: =H9*H21 -> 2543.2392 | I22: =I9*I21 -> 3117.9483 | J22: =J9*J21 -> 3689.9042
B25: B. BLINKIT
B26: Store Metrics
B27: Dark Store Count (EoY) | C27: - | D27: =KPIs!D133 -> 377 | E27: =KPIs!E133 -> 526 | F27: =KPIs!F133 -> 1301 | G27: =Assumptions!E53 -> 1950 | H27: =Assumptions!F53 -> 2600 | I27: =Assumptions!G53 -> 3300 | J27: =Assumptions!H53 -> 3700
B28: Net New Store Additions | C28: - | D28: 0 | E28: =KPIs!E134 -> 149 | F28: =KPIs!F134 -> 775 | G28: =G27-F27 -> 649 | H28: =H27-G27 -> 650 | I28: =I27-H27 -> 700 | J28: =J27-I27 -> 400
B29: Capex / New Store (₹ Cr) | C29: - | D29: - | E29: - | F29: =Assumptions!D68 -> 1.21 | G29: =Assumptions!E68 -> 1.4 | H29: =Assumptions!F68 -> 1.6 | I29: =Assumptions!G68 -> 1.7 | J29: =Assumptions!H68 -> 1.8
B30: Blinkit Capex (₹ Cr) | C30: - | D30: - | E30: - | F30: =F29*F28 -> 937.75 | G30: =G29*G28 -> 908.6 | H30: =H29*H28 -> 1040 | I30: =I29*I28 -> 1190 | J30: =J29*J28 -> 720
B32: Revenue Build
B33: NOV Growth % YoY | C33: - | D33: - | E33: 0.85 | F33: 1.13 | G33: =Assumptions!E38 -> 0.5 | H33: =Assumptions!F38 -> 0.5 | I33: =Assumptions!G38 -> 0.35 | J33: =Assumptions!H38 -> 0.2
B34: NOV (₹ Cr) [FY23 = Unaudited MIS] | C34: - | D34: =KPIs!D122 -> 5690 | E34: =KPIs!E122 -> 10503 | F34: =KPIs!F122 -> 22371 | G34: =F34*(1+G33) -> 33556.5 | H34: =G34*(1+H33) -> 50334.75 | I34: =H34*(1+I33) -> 67951.913 | J34: =I34*(1+J33) -> 81542.295
B35: Take Rate (Revenue ÷ NOV) | C35: - | D35: 0.142 | E35: 0.219 | F35: 0.233 | G35: =Assumptions!E43 -> 0.235 | H35: =Assumptions!F43 -> 0.24 | I35: =Assumptions!G43 -> 0.245 | J35: =Assumptions!H43 -> 0.25
B36: Blinkit Revenue (₹ Cr) | C36: - | D36: =KPIs!D123 -> 806 | E36: =KPIs!E123 -> 2301 | F36: =KPIs!F123 -> 5206 | G36: =G34*G35 -> 7885.7775 | H36: =H34*H35 -> 12080.34 | I36: =I34*I35 -> 16648.219 | J36: =J34*J35 -> 20385.574
B38: Profitability [Probability-Weighted: 40% Rational + 60% Irrational]
B39: EBITDA Margin - Rational Scenario (40%) | C39: - | D39: - | E39: - | F39: - | G39: 0.02 | H39: 0.035 | I39: 0.05 | J39: 0.06
B40: EBITDA Margin - Irrational Scenario (60%) | C40: - | D40: - | E40: - | F40: - | G40: 0.003 | H40: 0.01 | I40: 0.025 | J40: 0.035
B41: EBITDA Margin % of NOV - Probability-Weighted | C41: - | D41: - | E41: - | F41: - | G41: =0.4*G39+0.6*G40 -> 0.0098 | H41: =0.4*H39+0.6*H40 -> 0.02 | I41: =0.4*I39+0.6*I40 -> 0.035 | J41: =0.4*J39+0.6*J40 -> 0.045
B42: Adj EBITDA - Blinkit (₹ Cr) | C42: - | D42: =KPIs!D145 -> -1016 | E42: =KPIs!E145 -> -384 | F42: =KPIs!F145 -> -292 | G42: =G34*G41 -> 328.8537 | H42: =H34*H41 -> 1006.695 | I42: =I34*I41 -> 2378.3169 | J42: =J34*J41 -> 3669.4033
B45: C. HYPERPURE B2B SUPPLIES
B46: Revenue (₹ Cr) | C46: =KPIs!C151 -> 538 | D46: =KPIs!D151 -> 1506 | E46: =KPIs!E151 -> 3172 | F46: =KPIs!F151 -> 6196 | G46: =F46*(1+Assumptions!E75) -> 9913.6 | H46: =G46*(1+Assumptions!F75) -> 14374.72 | I46: =H46*(1+Assumptions!G75) -> 19405.872 | J46: =I46*(1+Assumptions!H75) -> 24257.34
B47: YoY Revenue Growth % | C47: =KPIs!C152 -> 1.7 | D47: =KPIs!D152 -> 1.8 | E47: =KPIs!E152 -> 1.11 | F47: =KPIs!F152 -> 0.95 | G47: =Assumptions!E75 -> 0.6 | H47: =Assumptions!F75 -> 0.45 | I47: =Assumptions!G75 -> 0.35 | J47: =Assumptions!H75 -> 0.25
B48: Adj EBITDA - Hyperpure (₹ Cr) | C48: =KPIs!C159 -> -139 | D48: =KPIs!D159 -> -194 | E48: =KPIs!E159 -> -126 | F48: =KPIs!F159 -> -84 | G48: =G46*G49 -> 99.136 | H48: =H46*H49 -> 287.4944 | I48: =I46*I49 -> 679.20552 | J48: =J46*J49 -> 1091.5803
B49: Adj EBITDA Margin % of Revenue | C49: =KPIs!C160 -> -0.258 | D49: =KPIs!D160 -> -0.129 | E49: =KPIs!E160 -> -0.039 | F49: =KPIs!F160 -> -0.014 | G49: =Assumptions!E80 -> 0.01 | H49: =Assumptions!F80 -> 0.02 | I49: =Assumptions!G80 -> 0.035 | J49: =Assumptions!H80 -> 0.045
B51: D. DISTRICT / GOING OUT [10% execution haircut on NOV growth]
...

Sheet 3-Statement
B2: 3-STATEMENT MODEL - ETERNAL LIMITED | ₹ Crores
B3: Particulars | C3: FY22A | D3: FY23A | E3: FY24A | F3: FY25A | G3: FY26E | H3: FY27E | I3: FY28E | J3: FY29E
B5: INCOME STATEMENT (₹ Crores)
B6: REVENUE FROM OPERATIONS
B7: Total Revenue from Operations | C7: ='Historical Financials'!C12 -> 4193 | D7: ='Historical Financials'!D12 -> 7079 | E7: ='Historical Financials'!E12 -> 12114 | F7: ='Historical Financials'!F12 -> 20243 | G7: ='Revenue Model'!G63 -> 28641.422 | H7: ='Revenue Model'!H63 -> 40122.272 | I7: ='Revenue Model'!I63 -> 53093.729 | J7: ='Revenue Model'!J63 -> 65159.791
B8: - Food Delivery | C8: ='Historical Financials'!C7 -> 3415 | D8: ='Historical Financials'!D7 -> 4533 | E8: ='Historical Financials'!E7 -> 6361 | F8: ='Historical Financials'!F7 -> 8080 | G8: ='Revenue Model'!G18 -> 9804.4902 | H8: ='Revenue Model'!H18 -> 12039.002 | I8: ='Revenue Model'!I18 -> 14652.013 | J8: ='Revenue Model'!J18 -> 17142.855
B9: - Blinkit Quick Commerce | C9: - | D9: ='Historical Financials'!D8 -> 806 | E9: ='Historical Financials'!E8 -> 2301 | F9: ='Historical Financials'!F8 -> 5206 | G9: ='Revenue Model'!G36 -> 7885.7775 | H9: ='Revenue Model'!H36 -> 12080.34 | I9: ='Revenue Model'!I36 -> 16648.219 | J9: ='Revenue Model'!J36 -> 20385.574
B10: - Hyperpure B2B | C10: ='Historical Financials'!C9 -> 538 | D10: ='Historical Financials'!D9 -> 1506 | E10: ='Historical Financials'!E9 -> 3172 | F10: ='Historical Financials'!F9 -> 6196 | G10: ='Revenue Model'!G46 -> 9913.6 | H10: ='Revenue Model'!H46 -> 14374.72 | I10: ='Revenue Model'!I46 -> 19405.872 | J10: ='Revenue Model'!J46 -> 24257.34
B11: - District / Going Out | C11: ='Historical Financials'!C10 -> - | D11: ='Historical Financials'!D10 -> - | E11: ='Historical Financials'!E10 -> 258 | F11: ='Historical Financials'!F10 -> 737 | G11: ='Revenue Model'!G54 -> 1012.554 | H11: ='Revenue Model'!H54 -> 1603.2105 | I11: ='Revenue Model'!I54 -> 2362.626 | J11: ='Revenue Model'!J54 -> 3349.0224
B12: - Others | C12: ='Historical Financials'!C11 -> 240 | D12: ='Historical Financials'!D11 -> 234 | E12: ='Historical Financials'!E11 -> 22 | F12: ='Historical Financials'!F11 -> 24 | G12: ='Revenue Model'!G59 -> 25 | H12: ='Revenue Model'!H59 -> 25 | I12: ='Revenue Model'!I59 -> 25 | J12: ='Revenue Model'!J59 -> 25
B13: YoY Revenue Growth % | C13: - | D13: =D7/C7-1 -> 0.68829001 | E13: =E7/D7-1 -> 0.71125865 | F13: =F7/E7-1 -> 0.67104177 | G13: =G7/F7-1 -> 0.41488029 | H13: =H7/G7-1 -> 0.40084779 | I13: =I7/H7-1 -> 0.32329816 | J13: =J7/I7-1 -> 0.22725964
B14: Other Income (Treasury Returns) | C14: ='Historical Financials'!C15 -> 495 | D14: ='Historical Financials'!D15 -> 681 | E14: ='Historical Financials'!E15 -> 847 | F14: ='Historical Financials'!F15 -> 1077 | G14: =Assumptions!E138*0.07 -> 1085 | H14: =Assumptions!F138*0.07 -> 945 | I14: =Assumptions!G138*0.07 -> 840 | J14: =Assumptions!H138*0.07 -> 770
B15: TOTAL INCOME | C15: =C7+C14 -> 4688 | D15: =D7+D14 -> 7760 | E15: =E7+E14 -> 12961 | F15: =F7+F14 -> 21320 | G15: =G7+G14 -> 29726.422 | H15: =H7+H14 -> 41067.272 | I15: =I7+I14 -> 53933.729 | J15: =J7+J14 -> 65929.791
B17: COST STRUCTURE
B18: Purchases of Stock-in-Trade | C18: ='Historical Financials'!C19 -> 552 | D18: ='Historical Financials'!D19 -> 1438 | E18: ='Historical Financials'!E19 -> 2887 | F18: ='Historical Financials'!F19 -> 5653 | G18: =ROUND(('Revenue Model'!G36+'Revenue Model'!G46)*Assumptions!E161,0) -> 8828 | H18: =ROUND(('Revenue Model'!H36+'Revenue Model'!H46)*Assumptions!F161,0) -> 13122 | I18: =ROUND(('Revenue Model'!I36+'Revenue Model'!I46)*Assumptions!G161,0) -> 17919 | J18: =ROUND(('Revenue Model'!J36+'Revenue Model'!J46)*Assumptions!H161,0) -> 22143
B19: Changes in Inventories | C19: ='Historical Financials'!C20 -> -43 | D19: ='Historical Financials'!D20 -> -28 | E19: ='Historical Financials'!E20 -> -5 | F19: ='Historical Financials'!F20 -> -88 | G19: =-(G73-F73) -> -114 | H19: =-(H73-G73) -> -141 | I19: =-(I73-H73) -> -109 | J19: =-(J73-I73) -> -67
B20: Delivery Partner & Fulfilment Costs | C20: ='Historical Financials'!C21 -> 1814 | D20: ='Historical Financials'!D21 -> 2537 | E20: ='Historical Financials'!E21 -> 3915 | F20: ='Historical Financials'!F21 -> 5728 | G20: =ROUND(G7*Assumptions!E108,0) -> 7876 | H20: =ROUND(H7*Assumptions!F108,0) -> 10632 | I20: =ROUND(I7*Assumptions!G108,0) -> 13539 | J20: =ROUND(J7*Assumptions!H108,0) -> 15964
B21: Cash Employee Benefits | C21: ='Historical Financials'!C27 -> 755 | D21: ='Historical Financials'!D27 -> 959 | E21: ='Historical Financials'!E27 -> 1144 | F21: ='Historical Financials'!F27 -> 1760 | G21: =ROUND(G7*Assumptions!E162,0) -> 2091 | H21: =ROUND(H7*Assumptions!F162,0) -> 2528 | I21: =ROUND(I7*Assumptions!G162,0) -> 2920 | J21: =ROUND(J7*Assumptions!H162,0) -> 3323
B22: ESOP / Share-Based Compensation | C22: ='Historical Financials'!C28 -> 878 | D22: ='Historical Financials'!D28 -> 506 | E22: ='Historical Financials'!E28 -> 515 | F22: ='Historical Financials'!F28 -> 798 | G22: =Assumptions!E163 -> 900 | H22: =Assumptions!F163 -> 950 | I22: =Assumptions!G163 -> 900 | J22: =Assumptions!H163 -> 850
B23: Advertising & Marketing | C23: ='Historical Financials'!C32 -> 1633 | D23: ='Historical Financials'!D32 -> 1465 | E23: ='Historical Financials'!E32 -> 526 | F23: ='Historical Financials'!F32 -> 863 | G23: =ROUND(G7*Assumptions!E113,0) -> 1432 | H23: =ROUND(H7*Assumptions!F113,0) -> 1926 | I23: =ROUND(I7*Assumptions!G113,0) -> 2389 | J23: =ROUND(J7*Assumptions!H113,0) -> 2932
B24: Technology & Platform Costs | C24: ='Historical Financials'!C33 -> 289 | D24: ='Historical Financials'!D33 -> 387 | E24: ='Historical Financials'!E33 -> 485 | F24: ='Historical Financials'!F33 -> 644 | G24: =ROUND(G7*Assumptions!E118,0) -> 859 | H24: =ROUND(H7*Assumptions!F118,0) -> 1123 | I24: =ROUND(I7*Assumptions!G118,0) -> 1380 | J24: =ROUND(J7*Assumptions!H118,0) -> 1629
B25: Other Operating Expenses (residual) | C25: ='Historical Financials'!C40-C20-'Historical Financials'!C32-'Historical Financials'!C33 -> 119 | D25: ='Historical Financials'!D40-D20-'Historical Financials'!D32-'Historical Financials'!D33 -> 1041 | E25: ='Historical Financials'!E40-E20-'Historical Financials'!E32-'Historical Financials'!E33 -> 2605 | F25: ='Historical Financials'!F40-F20-'Historical Financials'!F32-'Historical Financials'!F33 -> 4248 | G25: =ROUND(G7*0.08,0) -> 2291 | H25: =ROUND(H7*0.08,0) -> 3210 | I25: =ROUND(I7*0.08,0) -> 4247 | J25: =ROUND(J7*0.08,0) -> 5213
B27: ADJUSTED EBITDA | C27: ='Historical Financials'!C42 -> -973 | D27: ='Historical Financials'!D42 -> -765 | E27: ='Historical Financials'!E42 -> 372 | F27: ='Historical Financials'!F42 -> 1079 | G27: ='Revenue Model'!G69 -> 2274.8515 | H27: ='Revenue Model'!H69 -> 3753.0491 | I27: ='Revenue Model'!I69 -> 6529.8646 | J27: ='Revenue Model'!J69 -> 9407.7513
B28: Adj EBITDA Margin % | C28: =C27/C7 -> -0.23205342 | D28: =D27/D7 -> -0.10806611 | E28: =E27/E7 -> 0.030708271 | F28: =F27/F7 -> 0.053302376 | G28: =G27/G7 -> 0.079425229 | H28: =H27/H7 -> 0.093540291 | I28: =I27/I7 -> 0.12298749 | J28: =J27/J7 -> 0.1443797
B29: Less: ESOP Expense | C29: =C22 -> 878 | D29: =D22 -> 506 | E29: =E22 -> 515 | F29: =F22 -> 798 | G29: =G22 -> 900 | H29: =H22 -> 950 | I29: =I22 -> 900 | J29: =J22 -> 850
B30: REPORTED EBITDA | C30: =C27-C29 -> -1851 | D30: =D27-D29 -> -1271 | E30: =E27-E29 -> -143 | F30: =F27-F29 -> 281 | G30: =G27-G29 -> 1374.8515 | H30: =H27-H29 -> 2803.0491 | I30: =I27-I29 -> 5629.8646 | J30: =J27-J29 -> 8557.7513
B32: DEPRECIATION & AMORTISATION
B33: Depreciation on PPE | C33: ='Historical Financials'!C54 -> 287 | D33: ='Historical Financials'!D54 -> 212 | E33: ='Historical Financials'!E54 -> 524 | F33: ='Historical Financials'!F54 -> 247 | G33: =Assumptions!E127 -> 380 | H33: =Assumptions!F127 -> 480 | I33: =Assumptions!G127 -> 560 | J33: =Assumptions!H127 -> 620
B34: Amortisation of Intangibles | C34: ='Historical Financials'!C55 -> 108 | D34: ='Historical Financials'!D55 -> 256 | E34: ='Historical Financials'!E55 -> 242 | F34: ='Historical Financials'!F55 -> 287 | G34: =Assumptions!E128 -> 250 | H34: =Assumptions!F128 -> 200 | I34: =Assumptions!G128 -> 160 | J34: =Assumptions!H128 -> 130
B35: Depreciation on ROU Assets | C35: ='Historical Financials'!C56 -> 151 | D35: ='Historical Financials'!D56 -> 109 | E35: ='Historical Financials'!E56 -> 159 | F35: ='Historical Financials'!F56 -> 329 | G35: =Assumptions!E129 -> 500 | H35: =Assumptions!F129 -> 700 | I35: =Assumptions!G129 -> 870 | J35: =Assumptions!H129 -> 990
B36: Total D&A | C36: =SUM(C33:C35) -> 546 | D36: =SUM(D33:D35) -> 577 | E36: =SUM(E33:E35) -> 925 | F36: =SUM(F33:F35) -> 863 | G36: =SUM(G33:G35) -> 1130 | H36: =SUM(H33:H35) -> 1380 | I36: =SUM(I33:I35) -> 1590 | J36: =SUM(J33:J35) -> 1740
B38: EBIT | C38: =C27-C36 -> -1519 | D38: =D27-D36 -> -1342 | E38: =E27-E36 -> -553 | F38: =F27-F36 -> 216 | G38: =G27-G36 -> 1144.8515 | H38: =H27-H36 -> 2373.0491 | I38: =I27-I36 -> 4939.8646 | J38: =J27-J36 -> 7667.7513
B39: EBIT Margin % | C39: =C38/C7 -> -0.36227045 | D39: =D38/D7 -> -0.1895748 | E39: =E38/E7 -> -0.045649662 | F39: =F38/F7 -> 0.010670355 | G39: =G38/G7 -> 0.03997188 | H39: =H38/H7 -> 0.05914543 | I39: =I38/I7 -> 0.093040453 | J39: =J38/J7 -> 0.11767612
B41: FINANCE COSTS
B42: Interest on Lease Liabilities (INDAS 116) | C42: ='Historical Financials'!C64 -> 9 | D42: ='Historical Financials'!D64 -> 41 | E42: ='Historical Financials'!E64 -> 67 | F42: ='Historical Financials'!F64 -> 147 | G42: =ROUND(Assumptions!E140*0.085,0) -> 264 | H42: =ROUND(Assumptions!F140*0.085,0) -> 357 | I42: =ROUND(Assumptions!G140*0.085,0) -> 417 | J42: =ROUND(Assumptions!H140*0.085,0) -> 442
B43: Interest on Borrowings | C43: ='Historical Financials'!C63 -> 15 | D43: ='Historical Financials'!D63 -> 24 | E43: ='Historical Financials'!E63 -> - | F43: ='Historical Financials'!F63 -> - | G43: =Assumptions!E168 -> 5 | H43: =Assumptions!F168 -> 5 | I43: =Assumptions!G168 -> 5 | J43: =Assumptions!H168 -> 5
B44: Exceptional Items | C44: ='Historical Financials'!C66 -> 297 | D44: ='Historical Financials'!D66 -> 0 | E44: ='Historical Financials'!E66 -> 0 | F44: ='Historical Financials'!F66 -> 0 | G44: =Assumptions!E169 -> 0 | H44: =Assumptions!F169 -> 0 | I44: =Assumptions!G169 -> 0 | J44: =Assumptions!H169 -> 0
B45: PROFIT BEFORE TAX (PBT) | C45: ='Historical Financials'!C68 -> -1221 | D45: ='Historical Financials'!D68 -> -1015 | E45: ='Historical Financials'!E68 -> 291 | F45: ='Historical Financials'!F68 -> 697 | G45: =G38-G42-G43+G14+G44 -> 1960.8515 | H45: =H38-H42-H43+H14+H44 -> 2956.0491 | I45: =I38-I42-I43+I14+I44 -> 5357.8646 | J45: =J38-J42-J43+J14+J44 -> 7990.7513
B46: PBT Margin % | C46: =C45/C7 -> -0.29119962 | D46: =D45/D7 -> -0.14338183 | E46: =E45/E7 -> 0.024021793 | F46: =F45/F7 -> 0.034431655 | G46: =G45/G7 -> 0.068462086 | H46: =H45/H7 -> 0.073676013 | I46: =I45/I7 -> 0.10091332 | J46: =J45/J7 -> 0.12263316
B48: TAX
...

Sheet DCF + Sensitivity
B2: DCF VALUATION - ETERNAL LIMITED | Two-Stage DCF | Operating FCFF (Treasury Excluded)
B3: CMP: ₹249 per share | Market Cap: ₹2,40,303 Cr | 52-Week Range: ₹212–₹368 | April 2026
B4: SECTION 1 - WACC CALCULATION
B6: Metric | C6: Bear | D6: Base | E6: Bull | F6: Source / Notes
B7: Risk-Free Rate (10Y G-Sec) | C7: =Assumptions!$F$145 -> 0.068 | D7: =Assumptions!$F$145 -> 0.068 | E7: =Assumptions!$F$145 -> 0.068 | F7: RBI 10Y G-Sec, early 2026 - Assumptions!D149
B8: Equity Risk Premium (ERP) | C8: =Assumptions!$F$146 -> 0.055 | D8: =Assumptions!$F$146 -> 0.055 | E8: =Assumptions!$F$146 -> 0.055 | F8: Damodaran: US ERP 4.5% + India CRP 2.0% - Assumptions!D150
B9: Beta (Relevered) | C9: 1.2 | D9: =Assumptions!F147 -> 0.95 | E9: 0.75 | F9: Comps: DoorDash 1.30, Del.Hero 1.45, Sea 1.60 - Assumptions!D151
B10: Cost of Equity | C10: =C7+C9*C8 -> 0.134 | D10: =D7+D9*D8 -> 0.12025 | E10: =E7+E9*E8 -> 0.10925 | F10: CAPM: Rf+β×ERP = 6.8%+(1.3/1.1/0.95)×5.5%
B11: MODEL WACC | C11: =Assumptions!F150 -> 0.1395 | D11: =Assumptions!F149 -> 0.13125 | E11: =Assumptions!F151 -> 0.1175 | F11: Eternal is DEBT-FREE → WACC = Ke - Assumptions!D153/154/155
B12: Terminal Growth Rate | C12: =Assumptions!F153 -> 0.04 | D12: =Assumptions!F152 -> 0.045 | E12: =Assumptions!F154 -> 0.055 | F12: India nominal GDP 8-10%; conservative TGR
B14: SECTION 2 - STAGE 1 FCFF (FY26E–FY29E, from 3-Statement Tab FCFF Schedule)
B16: Metric | C16: FY26E | D16: FY27E | E16: FY28E | F16: FY29E | G16: Notes / Source
B17: EBIT (₹ Cr) | C17: ='3-Statement'!G38 -> 1144.8515 | D17: ='3-Statement'!H38 -> 2373.0491 | E17: ='3-Statement'!I38 -> 4939.8646 | F17: ='3-Statement'!J38 -> 7667.7513 | G17: From 3-Statement IS EBIT row
B18: Tax Rate | C18: =Assumptions!E123 -> 0.22 | D18: =Assumptions!F123 -> 0.22 | E18: =Assumptions!G123 -> 0.25 | F18: =Assumptions!H123 -> 0.25 | G18: From Assumptions tab row 127
B19: NOPAT | C19: =ROUND(C17*(1-C18),0) -> 893 | D19: =ROUND(D17*(1-D18),0) -> 1851 | E19: =ROUND(E17*(1-E18),0) -> 3705 | F19: =ROUND(F17*(1-F18),0) -> 5751
B20: Add: Total D&A (₹ Cr) | C20: ='3-Statement'!G36 -> 1130 | D20: ='3-Statement'!H36 -> 1380 | E20: ='3-Statement'!I36 -> 1590 | F20: ='3-Statement'!J36 -> 1740 | G20: From Assumptions tab rows 131+132+133
B21: Less: Total Capex (₹ Cr) | C21: =-(Assumptions!E137) -> -1100 | D21: =-(Assumptions!F137) -> -1450 | E21: =-(Assumptions!G137) -> -1300 | F21: =-(Assumptions!H137) -> -1000 | G21: From Assumptions tab row 141 - Blinkit 80% of total
B22: Less: Change in NWC (₹ Cr) | C22: =(30219*18/365)-(20243*18/365) -> 491.96712 | D22: =(42538*18/365)-(30219*18/365) -> 607.51233 | E22: =(56423*18/365)-(42538*18/365) -> 684.73973 | F22: =-(('3-Statement'!J7-'3-Statement'!I7)*18/365) -> -595.03866 | G22: Revenue×18days/365 change; Q3FY26 concall: Akshant "NWC ≤18 days target
B23: FCFF Stage 1 (₹ Cr) | C23: =SUM(C19:C22) -> 1414.9671 | D23: =SUM(D19:D22) -> 2388.5123 | E23: =SUM(E19:E22) -> 4679.7397 | F23: =SUM(F19:F22) -> 5895.9613
B25: SECTION 3 - STAGE 2 TRANSITION (FY30E–FY34E, Indicative Extrapolation)
B26: Metric | C26: FY30E | D26: FY31E | E26: FY32E | F26: FY33E | G26: FY34E | H26: FY35E | I26: FY36E | J26: Notes/Source
B27: Revenue Growth % | C27: 0.2 | D27: 0.18 | E27: 0.15 | F27: 0.13 | G27: 0.12 | H27: 0.1 | I27: 0.09 | J27: Tapering from 22.7% FY29 toward 12% steady state
B28: Revenue (₹ Cr) | C28: ='3-Statement'!J7*(1+C27) -> 78191.749 | D28: =C28*(1+D27) -> 92266.264 | E28: =D28*(1+E27) -> 106106.2 | F28: =E28*(1+F27) -> 119900.01 | G28: =F28*(1+G27) -> 134288.01 | H28: =G28*(1+H27) -> 147716.81 | I28: =H28*(1+I27) -> 161011.33 | J28: FY29E (₹69,238) × growth chain
B29: EBIT Margin % | C29: 0.15 | D29: 0.17 | E29: 0.19 | F29: 0.2 | G29: 0.21 | H29: 0.22 | I29: 0.22 | J29: DoorDash FY25 EBITDA 15%+; Eternal 22% EBIT by FY36 justified by Food+Blinkit maturity
B30: NOPAT (₹ Cr) | C30: =C28*C29*0.75 -> 8796.5718 | D30: =D28*D29*0.75 -> 11763.949 | E30: =E28*E29*0.75 -> 15120.134 | F30: =F28*F29*0.75 -> 17985.001 | G30: =G28*G29*0.75 -> 21150.362 | H30: =H28*H29*0.75 -> 24373.274 | I30: =I28*I29*0.75 -> 26566.869 | J30: Rev × EBIT% × (1−25%); 25% tax rate
B31: D&A (₹ Cr) | C31: =ROUND(C28*0.025,0) -> 1955 | D31: =ROUND(D28*0.023,0) -> 2122 | E31: =ROUND(E28*0.022,0) -> 2334 | F31: =ROUND(F28*0.021,0) -> 2518 | G31: =ROUND(G28*0.02,0) -> 2686 | H31: 2982 | I31: 3080 | J31: 2.5% tapering to 2.0% of revenue
B32: Capex (₹ Cr) | C32: =-ROUND(C28*0.012,0) -> -938 | D32: =-ROUND(D28*0.01,0) -> -923 | E32: =-ROUND(E28*0.01,0) -> -1061 | F32: =-ROUND(F28*0.01,0) -> -1199 | G32: =-ROUND(G28*0.01,0) -> -1343 | H32: =-ROUND(H28*0.015,0) -> -2216 | I32: =-ROUND(I28*0.015,0) -> -2415 | J32: 1.2% tapering to 1.0% - maintenance capex
B33: Change in NWC (₹ Cr) | C33: -300 | D33: -250 | E33: -200 | F33: -150 | G33: -100 | H33: -80 | I33: -60 | J33: Declining as growth slows
B34: FCFF Stage 2 (₹ Cr) | C34: =SUM(C30,C31)+C32+C33 -> 9513.5718 | D34: =SUM(D30,D31)+D32+D33 -> 12712.949 | E34: =SUM(E30,E31)+E32+E33 -> 16193.134 | F34: =SUM(F30,F31)+F32+F33 -> 19154.001 | G34: =SUM(G30,G31)+G32+G33 -> 22393.362 | H34: =SUM(H30,H31)+H32+H33 -> 25059.274 | I34: =SUM(I30,I31)+I32+I33 -> 27171.869 | J34: NOPAT + DA - Capex - NWC
B36: SECTION 4 - DCF VALUATION SUMMARY (Bear | Base | Bull)
B38: Metric | D38: Bear | E38: Base | F38: Bull
B39: WACC Used | D39: =C11 -> 0.1395 | E39: =D11 -> 0.13125 | F39: =E11 -> 0.1175
B40: TGR Used | D40: =C12 -> 0.04 | E40: =D12 -> 0.045 | F40: =E12 -> 0.055
B41: PV of Stage 1 FCFFs | D41: =$C$23/(1+D39)^0.5+$D$23/(1+D39)^1.5+$E$23/(1+D39)^2.5+$F$23/(1+D39)^3.5 -> 10398.372 | E41: =$C$23/(1+E39)^0.5+$D$23/(1+E39)^1.5+$E$23/(1+E39)^2.5+$F$23/(1+E39)^3.5 -> 10582.765 | F41: =$C$23/(1+F39)^0.5+$D$23/(1+F39)^1.5+$E$23/(1+F39)^2.5+$F$23/(1+F39)^3.5 -> 10901.865
B42: PV of Stage 2 FCFFs | D42: =$C$34/(1+D39)^4.5+$D$34/(1+D39)^5.5+$E$34/(1+D39)^6.5+$F$34/(1+D39)^7.5+$G$34/(1+D39)^8.5+$H$34/(1+D39)^9.5+$I$34/(1+D39)^10.5 -> 47130.704 | E42: =$C$34/(1+E39)^4.5+$D$34/(1+E39)^5.5+$E$34/(1+E39)^6.5+$F$34/(1+E39)^7.5+$G$34/(1+E39)^8.5+$H$34/(1+E39)^9.5+$I$34/(1+E39)^10.5 -> 49832.07 | F42: =$C$34/(1+F39)^4.5+$D$34/(1+F39)^5.5+$E$34/(1+F39)^6.5+$F$34/(1+F39)^7.5+$G$34/(1+F39)^8.5+$H$34/(1+F39)^9.5+$I$34/(1+F39)^10.5 -> 54756.948
B43: Terminal Value | D43: =$I$34*(1+D40)/(D39-D40) -> 284007.47 | E43: =$I$34*(1+E40)/(E39-E40) -> 329212.79 | F43: =$I$34*(1+F40)/(F39-F40) -> 458661.14
B44: PV of Terminal Value | D44: =D43/(1+D39)^11 -> 67526.174 | E44: =E43/(1+E39)^11 -> 84787.568 | F44: =F43/(1+F39)^11 -> 135135.39
B45: Terminal Value as % of Total EV | D45: =D44/(D41+D42+D44) -> 0.53997072 | E45: =E44/(E41+E42+E44) -> 0.58392675 | F45: =F44/(F41+F42+F44) -> 0.67300444
B46: ENTERPRISE VALUE (₹ Cr) | D46: =D41+D42+D44 -> 125055.25 | E46: =E41+E42+E44 -> 145202.4 | F46: =F41+F42+F44 -> 200794.2
B48: EV TO EQUITY BRIDGE
...

Sheet SOTP Valution
B2: STOP VALUATION - ETERNAL LIMITED
B3: Sum-of-the-Parts Valuation | FY28E Forward Multiples | Bear / Base / Bull Scenarios | April 2026
B5: SECTION 1 - METHODOLOGY & RATIONALE
B6: Food Delivery on EV/Adj.EBITDA (mature, profitable). Blinkit on EV/GOV (pre-maturity, GOV-based industry standard). Hyperpure on EV/Revenue (B2B, thin margins). District on EV/GOV (early- stage platform). Net Cash added at book. Leases deducted at book. Three scenarios via multiple ranges.
B8: SECTION 2 — SEGMENT VALUATION TABLE
B9: Segment | C9: Valuation Metric | D9: FY28E Value (₹ Cr) | E9: Bear Multiple | F9: Base Multiple | G9: Bull Multiple | H9: Bear EV (₹ Cr) | I9: Base EV (₹ Cr) | J9: Bull EV (₹ Cr) | K9: Multiple Justification
B10: Food Delivery (Zomato) | C10: EV / Adj. EBITDA (FY28E) | D10: =' SEGMENT P&L'!H15 -> 3117.9483 | E10: 35 | F10: 40 | G10: 48 | H10: =ROUND(E10*D10,0) -> 109128 | I10: =ROUND(F10*D10,0) -> 124718 | J10: =ROUND(G10*D10,0) -> 149662 | K10: Nomura: 40x FY28E. DoorDash ~34x NTM. FD EBITDA FY28E=₹3,118 Cr at 5.7% NOV margin. Bear=35x (competition), Base=40x (Nomura aligned), Bull=48x (India internet premium + leadership).
B11: Blinkit (Quick Commerce) | C11: EV / GOV (FY28E) | D11: =' SEGMENT P&L'!H28 -> 75503 | E11: 0.9 | F11: 1.2 | G11: 1.6 | H11: =ROUND(E11*D11,0) -> 67953 | I11: =ROUND(F11*D11,0) -> 90604 | J11: =ROUND(G11*D11,0) -> 120805 | K11: Nomura: 1.2x EV/GOV. Zepto private 1.0-1.3x. 45% QC market share. GOV FY28E=₹75,503 Cr. Bear=0.9x execution risk, Base=1.2x Nomura aligned, Bull=1.6x market dominance.
B12: Hyperpure (B2B Supply) | C12: EV / Revenue (FY28E) | D12: =' SEGMENT P&L'!H48 -> 19405.872 | E12: 0.5 | F12: 0.7 | G12: 0.9 | H12: =ROUND(E12*D12,0) -> 9703 | I12: =ROUND(F12*D12,0) -> 13584 | J12: =ROUND(G12*D12,0) -> 17465 | K12: B2B food supply chain. Revenue FY28E=₹19,406 Cr at 3.5% EBITDA margin. No listed comp. Bear=0.5x thin margins, Base=0.7x, Bull=0.9x scale benefit.
B13: District (Going-Out/Events) | C13: EV / GOV (FY28E) | D13: =' SEGMENT P&L'!H57 -> 27782 | E13: 0.2 | F13: 0.4 | G13: 0.5 | H13: =ROUND(E13*D13,0) -> 5556 | I13: =ROUND(F13*D13,0) -> 11113 | J13: =ROUND(G13*D13,0) -> 13891 | K13: Early-stage, loss-making. GOV FY28E=₹27,782 Cr. EBITDA turns positive FY28E. Deeply discounted. Bear=0.2x (optionality), Base=0.35x, Bull=0.5x (category proves out).
B14: Others / Platform Services | C14: EV / Revenue (FY28E) | D14: =' SEGMENT P&L'!H72 -> 25 | E14: 0.5 | F14: 0.5 | G14: 0.5 | H14: =ROUND(E14*D14,0) -> 13 | I14: =ROUND(F14*D14,0) -> 13 | J14: =ROUND(G14*D14,0) -> 13 | K14: Negligible contribution. Flat multiple all scenarios.
B16: TOTAL SEGMENT EV (₹ Cr) | H16: =SUM(H10:H15) -> 192353 | I16: =SUM(I10:I15) -> 240032 | J16: =SUM(J10:J15) -> 301836
B17: Food Delivery % of Segment EV | H17: =TEXT(ROUND(H10/H16*100,1),"0.0")&"%" -> 56.7% | I17: =TEXT(ROUND(I10/I16*100,1),"0.0")&"%" -> 52.0% | J17: =TEXT(ROUND(J10/J16*100,1),"0.0")&"%" -> 49.6%
B18: Blinkit % of Segment EV | H18: =TEXT(ROUND(H11/H16*100,1),"0.0")&"%" -> 35.3% | I18: =TEXT(ROUND(I11/I16*100,1),"0.0")&"%" -> 37.7% | J18: =TEXT(ROUND(J11/J16*100,1),"0.0")&"%" -> 40.0%
B20: SECTION 2 - EV TO EQUITY BRIDGE
B21: Total Segment EV (₹ Cr) | H21: =H16 -> 192353 | I21: =I16 -> 240032 | J21: =J16 -> 301836
B22: Add: Net Liquid Assets - FY25A (₹ Cr) | H22: ='DCF + Sensitivity'!D50 -> 16806 | I22: ='DCF + Sensitivity'!E50 -> 16806 | J22: ='DCF + Sensitivity'!F50 -> 16806
B23: Less: Lease Liabilities - FY25A (₹ Cr) | H23: ='DCF + Sensitivity'!D51 -> -2045 | I23: ='DCF + Sensitivity'!E51 -> -2045 | J23: ='DCF + Sensitivity'!F51 -> -2045
B24: Less: Financial Debt (₹ Cr) | H24: ='DCF + Sensitivity'!D52 -> 0 | I24: ='DCF + Sensitivity'!E52 -> 0 | J24: ='DCF + Sensitivity'!F52 -> 0
B26: EQUITY VALUE (₹ Cr) | H26: =H21+H22+H23+H24 -> 207114 | I26: =I21+I22+I23+I24 -> 254793 | J26: =J21+J22+J23+J24 -> 316597
B27: Diluted Shares Outstanding (Cr) | H27: ='DCF + Sensitivity'!D54 -> 940 | I27: ='DCF + Sensitivity'!E54 -> 940 | J27: ='DCF + Sensitivity'!F54 -> 940
B29: SECTION 3 - SOTP VALUATION SUMMARY
B30: Metric | C30: Bear Case | D30: Base Case | E30: Bull Case | F30: Notes
B31: Equity Value (₹ Cr) | C31: =H26 -> 207114 | D31: =I26 -> 254793 | E31: =J26 -> 316597 | F31: Post net cash add & lease deduction
B32: SOTP Intrinsic Value Per Share (₹) | C32: =ROUND(H26/H27,0) -> 220 | D32: =ROUND(I26/I27,0) -> 271 | E32: =ROUND(J26/J27,0) -> 337 | F32: FY28E multiples - Nomura aligned
B33: CMP — April 2026 (₹) | C33: 249 | D33: 249 | E33: 249 | F33: Consol FY28E Adj EBITDA = ₹6,609 Cr (sanity check)
B34: Upside / (Downside) vs CMP | C34: =TEXT(ROUND((C32/C33-1)*100,1),"0.0")&"%" -> -11.6% | D34: =TEXT(ROUND((D32/D33-1)*100,1),"0.0")&"%" -> 8.8% | E34: =TEXT(ROUND((E32/E33-1)*100,1),"0.0")&"%" -> 35.3%
B35: Implied EV / Consol Adj EBITDA FY28E | C35: =TEXT(ROUND(H16/' SEGMENT P&L'!$H$73,1),"0.0")&"x" -> 29.5x | D35: =TEXT(ROUND(I16/' SEGMENT P&L'!$H$73,1),"0.0")&"x" -> 36.8x | E35: =TEXT(ROUND(J16/' SEGMENT P&L'!$H$73,1),"0.0")&"x" -> 46.2x
B36: Implied P/E FY28E | C36: =TEXT(ROUND(C32*'DCF + Sensitivity'!$E$54/'3-Statement'!$I$53,1),"0.0")&"x" -> 50.9x | D36: =TEXT(ROUND(D32*'DCF + Sensitivity'!$E$54/'3-Statement'!$I$53,1),"0.0")&"x" -> 62.7x | E36: =TEXT(ROUND(E32*'DCF + Sensitivity'!$E$54/'3-Statement'!$I$53,1),"0.0")&"x" -> 77.9x | F36: PAT FY28E = ₹4,124 Cr per 3-Statement
B38: SECTION 5 — SOTP vs DCF RECONCILIATION
B39: Method | C39: Bear (₹) | D39: Base (₹) | E39: Bull (₹) | F39: Weight | G39: Rationale
B40: DCF Valuation | C40: ='DCF + Sensitivity'!C56 -> 148.74069 | D40: ='DCF + Sensitivity'!D56 -> 170.17383 | E40: ='DCF + Sensitivity'!E56 -> 229.31405 | F40: 0.6 | G40: Captures long-run terminal economics - majority weight
B41: SOTP Valuation | C41: =C32 -> 220 | D41: =D32 -> 271 | E41: =E32 -> 337 | F41: 0.4 | G41: Near-term segment multiples - Blinkit optionality captured
B43: BLENDED INTRINSIC VALUE (₹) | C43: =ROUND(C40*0.6+C41*0.4,0) -> 177 | D43: =ROUND(D40*0.6+D41*0.4,0) -> 211 | E43: =ROUND(E40*0.6+E41*0.4,0) -> 272
B44: Investment Rating | D44: HOLD
B45: 12-Month Target Price — Base Case (₹) | D45: =D43 -> 211
B46: CMP (₹) | D46: 249
B47: Upside / (Downside) to Target | D47: =TEXT(ROUND((D45/D46-1)*100,1),"0.0")&"%" -> -15.3%
B49: SECTION 6 — KEY ASSUMPTIONS & ANALYST BENCHMARKS
B50: 1. FOOD DELIVERY (EV/EBITDA 35–48x FY28E): Nomura uses 40x FY28E EBITDA. DoorDash 34x NTM. FD EBITDA FY28E = ₹3,118 Cr (5.7% NOV margin, 19% GOV growth). Base=40x Nomura-aligned. Bull=48x India internet premium + margin expansion.
...

Sheet Comps
B2: COMPARABLE COMPANY ANALYSIS - ETERNAL LIMITED | April 2026
B3: Sources: NSE/BSE live prices | DoorDash FY2025 10-K | Swiggy FY25 Annual Report | Conversion: ₹84/$
B5: SECTION 1 — PEER UNIVERSE
B6: Company | C6: Ticker | D6: CMP | E6: Mkt Cap (₹ Cr) | F6: EV (₹ Cr) | G6: Why Included
B7: ETERNAL LIMITED ← Subject | C7: NSE: ETERNAL | D7: ₹249 | E7: 240303 | F7: 225524 | G7: Subject company - food+QC+B2B+GoingOut
B8: SWIGGY LIMITED | C8: NSE: SWIGGY | D8: ₹272 | E8: 70767 | F8: 69162 | G8: Only direct Indian comp - food+QC+OOH
B9: DOORDASH INC | C9: NASDAQ: DASH | D9: 195 | E9: 646800 | F9: 621600 | G9: Global food delivery leader, profitable FY25
B10: DELIVERY HERO SE | C10: XETRA: DHER | D10: €0.85 | E10: 23000 | F10: 22000 | G10: Intl QC pioneer - verify Bloomberg
B11: SEA LIMITED | C11: NYSE: SE | D11: 29 | E11: 117600 | F11: 115000 | G11: SE Asia multi-vertical platform - proxy
B13: SECTION 2 — FINANCIAL METRICS SUMMARY
B14: Metric | C14: Eternal FY25A | D14: Eternal FY26E | E14: Swiggy FY25A | F14: DoorDash FY2025 | G14: Notes
B15: Revenue (₹ Cr) | C15: ='Historical Financials'!F12 -> 20243 | D15: ='3-Statement'!G7 -> 28641.422 | E15: 11247 | F15: 1152232 | G15: DoorDash $13.717B × 84 = ₹11.52L Cr
B16: Revenue Growth % (YoY) | C16: ='Historical Financials'!F13 -> 0.67104177 | D16: ='3-Statement'!G13 -> 0.41488029 | E16: 0.449 | F16: 0.279 | G16: Eternal 67% FY25 - highest among peers
B17: Adj. EBITDA (₹ Cr) | C17: ='3-Statement'!F27 -> 1079 | D17: ='3-Statement'!G27 -> 2274.8515 | E17: -2786 | F17: 129948 | G17: Swiggy still deeply loss-making -n/m for multiples
B18: Adj. EBITDA Margin % | C18: ='3-Statement'!F28 -> 0.053302376 | D18: ='3-Statement'!G28 -> 0.079425229 | E18: -0.248 | F18: 0.113 | G18: DoorDash 11.3% = Eternal's steady-state target
B19: PAT (₹ Cr) | C19: ='3-Statement'!F53 -> 527 | D19: ='3-Statement'!G53 -> 1593.8515 | E19: -3117 | F19: 78540 | G19: DoorDash $935M FY25 net income × 84
B21: SECTION 3 — TRADING MULTIPLES
B22: Multiple | C22: Eternal | D22: Swiggy | E22: DoorDash | F22: Peer Median | G22: Notes
B23: EV / Revenue - LTM (FY25A) | C23: 11.1x | D23: 6.1x | E23: 0.5x | F23: 5.8x | G23: Eternal 83% premium vs peers — Blinkit QC optionality
B24: EV / Revenue - NTM (FY26E) | C24: 7.5x | D24: 4.5x | E24: 4.1x | F24: 4.3x | G24: Eternal still at significant premium even on NTM
B25: EV / Adj. EBITDA - NTM | C25: 96.6x | D25: n/m | E25: 34.5x | F25: 34.5x | G25: Swiggy negative EBITDA → n/m; DoorDash = benchmark
B26: P/E - NTM | C26: 239x | D26: n/m | E26: 55x | F26: 55x | G26: All high-growth; P/E less meaningful here
B27: EV / B2C GOV (FY25A) | C27: 3.0x | D27: 2.0x | E27: 0.7x | F27: 1.5x | G27: India premium justified by higher GOV growth rate
B29: SECTION 4 — IMPLIED VALUATION FOR ETERNAL (Applying Peer Multiples to FY26E)
B30: Method | C30: Multiple Applied | D30: Eternal FY26E Metric (₹ Cr) | E30: Implied EV (₹ Cr) | F30: Implied Price (₹) | G30: vs CMP ₹249
B31: EV/Revenue 4.0x (Peer Median) | C31: 4 | D31: ='3-Statement'!$G$7 -> 28641.422 | E31: =C31*D31 -> 114565.69 | F31: =(E31+16806-2045)/940 -> 137.58158 | G31: =F31/249-1 -> -0.44746353
B32: EV/Revenue 5.0x (75th Pct) | C32: 5 | D32: ='3-Statement'!$G$7 -> 28641.422 | E32: =C32*D32 -> 143207.11 | F32: =(E32+16806-2045)/940 -> 168.05118 | G32: =F32/249-1 -> -0.32509567
B33: EV/Revenue 7.5x (Eternal Current NTM) | C33: 7.5 | D33: ='3-Statement'!$G$7 -> 28641.422 | E33: =C33*D33 -> 214810.66 | F33: =(E33+16806-2045)/940 -> 244.22517 | G33: =F33/249-1 -> -0.019176011
B34: EV/Revenue 9.0x (Growth Premium) | C34: 9 | D34: ='3-Statement'!$G$7 -> 28641.422 | E34: =C34*D34 -> 257772.8 | F34: =(E34+16806-2045)/940 -> 289.92957 | G34: =F34/249-1 -> 0.16437578
B35: EV/EBITDA 34.5x (DoorDash benchmark) | C35: 34.5 | D35: ='3-Statement'!$G$27 -> 2274.8515 | E35: =C35*D35 -> 78482.376 | F35: =(E35+16806-2045)/940 -> 99.195081 | G35: =F35/249-1 -> -0.60162618
B36: EV/EBITDA 50x | C36: 50 | D36: ='3-Statement'!$G$27 -> 2274.8515 | E36: =C36*D36 -> 113742.57 | F36: =(E36+16806-2045)/940 -> 136.70593 | G36: =F36/249-1 -> -0.4509802
B37: EV/EBITDA 75x | C37: 75 | D37: ='3-Statement'!$G$27 -> 2274.8515 | E37: =C37*D37 -> 170613.86 | F37: =(E37+16806-2045)/940 -> 197.2073 | G37: =F37/249-1 -> -0.20800282
B39: SECTION 5 — KEY ANALYTICAL OBSERVATIONS
